<?xml version="1.0"?>
<robot xmlns:xacro="http://www.ros.org/wiki/xacro"
  name="vampire_steak">

  <!-- Loading file with sensor macros -->
  <xacro:include filename="$(find uuv_sensor_ros_plugins)/urdf/sensor_snippets.xacro"/>

  <xacro:macro name="vampire_steak_base" params="namespace">

    <xacro:default_pose_3d namespace="${namespace}" parent_link="${namespace}/base_link" />

    <link name="${namespace}/base_link">
      <inertial>
        <origin
          xyz="0.0 0.0 0.0"
          rpy="0 0 0" />
        <mass
          value="1.0" />
        <inertia
          ixx="1.0E-5"
          ixy="0.0"
          ixz="0.0"
          iyy="1.0E-5"
          iyz="0.0"
          izz="1.0E-5" />
      </inertial>
      <visual>
        <geometry>
          <mesh filename="model://vampire_stake/vampire_board.dae"/>
        </geometry>
      </visual>
      <collision>
        <geometry>
          <mesh filename="model://vampire_stake/vampire_board.dae"/>
        </geometry>
      </collision>
    </link>

    <link name="${namespace}/lever_link">
      <inertial>
        <origin
          xyz="0.0 0.0 0.0"
          rpy="0 0 0" />
        <mass
          value="1.0" />
        <inertia
          ixx="1.0E-5"
          ixy="0.0"
          ixz="0.0"
          iyy="1.0E-5"
          iyz="0.0"
          izz="1.0E-5" />
      </inertial>
      <visual>
        <geometry>
          <mesh filename="model://vampire_stake/vampire_lever.dae"/>
        </geometry>
      </visual>
      <collision>
        <geometry>
          <mesh filename="model://vampire_stake/vampire_lever.dae"/>
        </geometry>
      </collision>
    </link>

    <joint name="${namespace}/lever_joint" type="prismatic">
        <child link="${namespace}/lever_link"/>
        <parent link="${namespace}/base_link"/>
        <dynamics damping="0.1" friction="0.2"/>
        <limit effort="30" velocity="1.0" lower="-0.05" upper="0.45" />
    </joint>

    <link name="${namespace}/magic_base_link">
      <inertial>
        <origin
          xyz="0.0 1.0 -2.0"
          rpy="0 0 0" />
        <mass
          value="10.0" />
        <inertia
          ixx="1.0E-5"
          ixy="0.0"
          ixz="0.0"
          iyy="1.0E-5"
          iyz="0.0"
          izz="1.0E-5" />
      </inertial>
      <visual>
        <origin
          xyz="0.3 0 -1.5"
          rpy="0 0 0" />
        <geometry>
          <box size="1.0 1.0 0.1"/>
        </geometry>
      </visual>
      <collision>
        <origin
          xyz="0.3 0 -1.5"
          rpy="0 0 0" />
        <geometry>
          <box size="1.0 1.0 0.1"/>
        </geometry>
      </collision>
    </link>

    <joint name="${namespace}/magic_base_joint" type="fixed">
        <child link="${namespace}/magic_base_link"/>
        <parent link="${namespace}/base_link"/>
    </joint>

    <gazebo>
      <static>true</static>
    </gazebo>

  </xacro:macro>

  <xacro:vampire_steak_base namespace="$(arg namespace)"/>

</robot>
